Workbook

Sheet MIL-STD_1553_Registers
A1: Registers | B1: Add | C1: Address | E1: Read/Write | F1: Default | G1: Default | H1: 15 | I1: 14 | J1: 13 | K1: 12 | L1: 11 | M1: 10 | N1: 9 | O1: 8 | P1: 7 | Q1: 6 | R1: 5 | S1: 4 | T1: 3 | U1: 2 | V1: 1 | W1: 0 | X1: Register deifnitions | Y1: Reset Assignment | Z1: RD command | AA1: Wr Command
A2: reg_status | B2: 0 | C2: =CONCATENATE("0x",DEC2HEX(B2,4)) -> 0x0000 | D2: =CONCATENATE(A2," (",C2,")") -> reg_status (0x0000) | E2: Read | F2: 0000 | G2: =CONCATENATE("0x",F2) -> 0x0000 | H2: TxAvail1 | I2: TxAvail2 | J2: Tx1_Off | K2: Tx2_Off | L2: Inhibit T/F | M2: DBC_accepted | N2: Synchronize | O2: InitiateBIT | P2: NewModeDatTx | Q2: NewModeDatRx | R2: NewMode | S2: NewRT2RTTX | T2: NewRT2RTRX | U2: NewBCRTTX | V2: Bus2Irq | W2: Bus1Irq | X2: =CONCATENATE("const static uint16_t c_Mil1553_w",A2, " = ",C2,";") -> const static uint16_t c_Mil1553_wreg_status = 0x0000; | Y2: =CONCATENATE(A2," <= X""",F2,""";") -> reg_status <= X"0000"; | Z2: =CONCATENATE(" when X""",C2,""" => DataOut <= ",A2,";") -> when X"0x0000" => DataOut <= reg_status; | AA2: =CONCATENATE(" when X""",C2,""" => ",A2," <= DataIn;") -> when X"0x0000" => reg_status <= DataIn;
A3: reg_intr_mask | B3: =B2+1 -> 1 | C3: =CONCATENATE("0x",DEC2HEX(B3,4)) -> 0x0001 | D3: =CONCATENATE(A3," (",C3,")") -> reg_intr_mask (0x0001) | E3: Read/Write | F3: 0000 | G3: =CONCATENATE("0x",F3) -> 0x0000 | H3: TxAvail1 | I3: TxAvail2 | J3: Tx1_Off | K3: Tx2_Off | L3: Inhibit T/F | M3: DBC_accepted | N3: Synchronize | O3: InitiateBIT | V3: Bus2Irq | W3: Bus1Irq | X3: =CONCATENATE("const static uint16_t c_Mil1553_w",A3, " = ",C3,";") -> const static uint16_t c_Mil1553_wreg_intr_mask = 0x0001; | Y3: =CONCATENATE(A3," <= X""",F3,""";") -> reg_intr_mask <= X"0000"; | Z3: =CONCATENATE(" when X""",C3,""" => DataOut <= ",A3,";") -> when X"0x0001" => DataOut <= reg_intr_mask; | AA3: =CONCATENATE(" when X""",C3,""" => ",A3," <= DataIn;") -> when X"0x0001" => reg_intr_mask <= DataIn;
A4: reg_clear_bits | B4: =B3+1 -> 2 | C4: =CONCATENATE("0x",DEC2HEX(B4,4)) -> 0x0002 | D4: =CONCATENATE(A4," (",C4,")") -> reg_clear_bits (0x0002) | E4: Read/Write | F4: 0000 | G4: =CONCATENATE("0x",F4) -> 0x0000 | L4: Synchronize | M4: InitiateBIT | X4: =CONCATENATE("const static uint16_t c_Mil1553_w",A4, " = ",C4,";") -> const static uint16_t c_Mil1553_wreg_clear_bits = 0x0002; | Y4: =CONCATENATE(A4," <= X""",F4,""";") -> reg_clear_bits <= X"0000"; | Z4: =CONCATENATE(" when X""",C4,""" => DataOut <= ",A4,";") -> when X"0x0002" => DataOut <= reg_clear_bits; | AA4: =CONCATENATE(" when X""",C4,""" => ",A4," <= DataIn;") -> when X"0x0002" => reg_clear_bits <= DataIn;
A5: reg_tmr_1us | B5: =B4+1 -> 3 | C5: =CONCATENATE("0x",DEC2HEX(B5,4)) -> 0x0003 | D5: =CONCATENATE(A5," (",C5,")") -> reg_tmr_1us (0x0003) | E5: Read/Write | F5: 0063 | G5: =CONCATENATE("0x",F5) -> 0x0063 | X5: =CONCATENATE("const static uint16_t c_Mil1553_w",A5, " = ",C5,";") -> const static uint16_t c_Mil1553_wreg_tmr_1us = 0x0003; | Y5: =CONCATENATE(A5," <= X""",F5,""";") -> reg_tmr_1us <= X"0063"; | Z5: =CONCATENATE(" when X""",C5,""" => DataOut <= ",A5,";") -> when X"0x0003" => DataOut <= reg_tmr_1us; | AA5: =CONCATENATE(" when X""",C5,""" => ",A5," <= DataIn;") -> when X"0x0003" => reg_tmr_1us <= DataIn;
A6: reg_tmr_GAP | B6: =B5+1 -> 4 | C6: =CONCATENATE("0x",DEC2HEX(B6,4)) -> 0x0004 | D6: =CONCATENATE(A6," (",C6,")") -> reg_tmr_GAP (0x0004) | E6: Read/Write | F6: 018F | G6: =CONCATENATE("0x",F6) -> 0x018F | X6: =CONCATENATE("const static uint16_t c_Mil1553_w",A6, " = ",C6,";") -> const static uint16_t c_Mil1553_wreg_tmr_GAP = 0x0004; | Y6: =CONCATENATE(A6," <= X""",F6,""";") -> reg_tmr_GAP <= X"018F"; | Z6: =CONCATENATE(" when X""",C6,""" => DataOut <= ",A6,";") -> when X"0x0004" => DataOut <= reg_tmr_GAP; | AA6: =CONCATENATE(" when X""",C6,""" => ",A6," <= DataIn;") -> when X"0x0004" => reg_tmr_GAP <= DataIn;
A7: reg_tmr_NRP | B7: =B6+1 -> 5 | C7: =CONCATENATE("0x",DEC2HEX(B7,4)) -> 0x0005 | D7: =CONCATENATE(A7," (",C7,")") -> reg_tmr_NRP (0x0005) | E7: Read/Write | F7: 0577 | G7: =CONCATENATE("0x",F7) -> 0x0577 | X7: =CONCATENATE("const static uint16_t c_Mil1553_w",A7, " = ",C7,";") -> const static uint16_t c_Mil1553_wreg_tmr_NRP = 0x0005; | Y7: =CONCATENATE(A7," <= X""",F7,""";") -> reg_tmr_NRP <= X"0577"; | Z7: =CONCATENATE(" when X""",C7,""" => DataOut <= ",A7,";") -> when X"0x0005" => DataOut <= reg_tmr_NRP; | AA7: =CONCATENATE(" when X""",C7,""" => ",A7," <= DataIn;") -> when X"0x0005" => reg_tmr_NRP <= DataIn;
A8: reg_tmr_REP | B8: =B7+1 -> 6 | C8: =CONCATENATE("0x",DEC2HEX(B8,4)) -> 0x0006 | D8: =CONCATENATE(A8," (",C8,")") -> reg_tmr_REP (0x0006) | E8: Read/Write | F8: 195 | G8: =CONCATENATE("0x",F8) -> 0x195 | X8: =CONCATENATE("const static uint16_t c_Mil1553_w",A8, " = ",C8,";") -> const static uint16_t c_Mil1553_wreg_tmr_REP = 0x0006; | Y8: =CONCATENATE(A8," <= X""",F8,""";") -> reg_tmr_REP <= X"195"; | Z8: =CONCATENATE(" when X""",C8,""" => DataOut <= ",A8,";") -> when X"0x0006" => DataOut <= reg_tmr_REP; | AA8: =CONCATENATE(" when X""",C8,""" => ",A8," <= DataIn;") -> when X"0x0006" => reg_tmr_REP <= DataIn;
A9: reg_tmr_SAF | B9: =B8+1 -> 7 | C9: =CONCATENATE("0x",DEC2HEX(B9,4)) -> 0x0007 | D9: =CONCATENATE(A9," (",C9,")") -> reg_tmr_SAF (0x0007) | E9: Read/Write | F9: 031F | G9: =CONCATENATE("0x",F9) -> 0x031F | X9: =CONCATENATE("const static uint16_t c_Mil1553_w",A9, " = ",C9,";") -> const static uint16_t c_Mil1553_wreg_tmr_SAF = 0x0007; | Y9: =CONCATENATE(A9," <= X""",F9,""";") -> reg_tmr_SAF <= X"031F"; | Z9: =CONCATENATE(" when X""",C9,""" => DataOut <= ",A9,";") -> when X"0x0007" => DataOut <= reg_tmr_SAF; | AA9: =CONCATENATE(" when X""",C9,""" => ",A9," <= DataIn;") -> when X"0x0007" => reg_tmr_SAF <= DataIn;
A10: reg_legal_subaddr1 | B10: =B9+1 -> 8 | C10: =CONCATENATE("0x",DEC2HEX(B10,4)) -> 0x0008 | D10: =CONCATENATE(A10," (",C10,")") -> reg_legal_subaddr1 (0x0008) | E10: Read/Write | F10: FFFF | G10: =CONCATENATE("0x",F10) -> 0xFFFF | X10: =CONCATENATE("const static uint16_t c_Mil1553_w",A10, " = ",C10,";") -> const static uint16_t c_Mil1553_wreg_legal_subaddr1 = 0x0008; | Y10: =CONCATENATE(A10," <= X""",F10,""";") -> reg_legal_subaddr1 <= X"FFFF"; | Z10: =CONCATENATE(" when X""",C10,""" => DataOut <= ",A10,";") -> when X"0x0008" => DataOut <= reg_legal_subaddr1; | AA10: =CONCATENATE(" when X""",C10,""" => ",A10," <= DataIn;") -> when X"0x0008" => reg_legal_subaddr1 <= DataIn;
A11: reg_legal_subaddr2 | B11: =B10+1 -> 9 | C11: =CONCATENATE("0x",DEC2HEX(B11,4)) -> 0x0009 | D11: =CONCATENATE(A11," (",C11,")") -> reg_legal_subaddr2 (0x0009) | E11: Read/Write | F11: FFFF | G11: =CONCATENATE("0x",F11) -> 0xFFFF | X11: =CONCATENATE("const static uint16_t c_Mil1553_w",A11, " = ",C11,";") -> const static uint16_t c_Mil1553_wreg_legal_subaddr2 = 0x0009; | Y11: =CONCATENATE(A11," <= X""",F11,""";") -> reg_legal_subaddr2 <= X"FFFF"; | Z11: =CONCATENATE(" when X""",C11,""" => DataOut <= ",A11,";") -> when X"0x0009" => DataOut <= reg_legal_subaddr2; | AA11: =CONCATENATE(" when X""",C11,""" => ",A11," <= DataIn;") -> when X"0x0009" => reg_legal_subaddr2 <= DataIn;
A12: reg_legal_rx_mode1 | B12: =B11+1 -> 10 | C12: =CONCATENATE("0x",DEC2HEX(B12,4)) -> 0x000A | D12: =CONCATENATE(A12," (",C12,")") -> reg_legal_rx_mode1 (0x000A) | E12: Read/Write | F12: 0000 | G12: =CONCATENATE("0x",F12) -> 0x0000 | X12: =CONCATENATE("const static uint16_t c_Mil1553_w",A12, " = ",C12,";") -> const static uint16_t c_Mil1553_wreg_legal_rx_mode1 = 0x000A; | Y12: =CONCATENATE(A12," <= X""",F12,""";") -> reg_legal_rx_mode1 <= X"0000"; | Z12: =CONCATENATE(" when X""",C12,""" => DataOut <= ",A12,";") -> when X"0x000A" => DataOut <= reg_legal_rx_mode1; | AA12: =CONCATENATE(" when X""",C12,""" => ",A12," <= DataIn;") -> when X"0x000A" => reg_legal_rx_mode1 <= DataIn;
A13: reg_legal_rx_mode2 | B13: =B12+1 -> 11 | C13: =CONCATENATE("0x",DEC2HEX(B13,4)) -> 0x000B | D13: =CONCATENATE(A13," (",C13,")") -> reg_legal_rx_mode2 (0x000B) | E13: Read/Write | F13: 0032 | G13: =CONCATENATE("0x",F13) -> 0x0032 | X13: =CONCATENATE("const static uint16_t c_Mil1553_w",A13, " = ",C13,";") -> const static uint16_t c_Mil1553_wreg_legal_rx_mode2 = 0x000B; | Y13: =CONCATENATE(A13," <= X""",F13,""";") -> reg_legal_rx_mode2 <= X"0032"; | Z13: =CONCATENATE(" when X""",C13,""" => DataOut <= ",A13,";") -> when X"0x000B" => DataOut <= reg_legal_rx_mode2; | AA13: =CONCATENATE(" when X""",C13,""" => ",A13," <= DataIn;") -> when X"0x000B" => reg_legal_rx_mode2 <= DataIn;
A14: reg_legal_tx_mode1 | B14: =B13+1 -> 12 | C14: =CONCATENATE("0x",DEC2HEX(B14,4)) -> 0x000C | D14: =CONCATENATE(A14," (",C14,")") -> reg_legal_tx_mode1 (0x000C) | E14: Read/Write | F14: 01FF | G14: =CONCATENATE("0x",F14) -> 0x01FF | X14: =CONCATENATE("const static uint16_t c_Mil1553_w",A14, " = ",C14,";") -> const static uint16_t c_Mil1553_wreg_legal_tx_mode1 = 0x000C; | Y14: =CONCATENATE(A14," <= X""",F14,""";") -> reg_legal_tx_mode1 <= X"01FF"; | Z14: =CONCATENATE(" when X""",C14,""" => DataOut <= ",A14,";") -> when X"0x000C" => DataOut <= reg_legal_tx_mode1; | AA14: =CONCATENATE(" when X""",C14,""" => ",A14," <= DataIn;") -> when X"0x000C" => reg_legal_tx_mode1 <= DataIn;
A15: reg_legal_tx_mode2 | B15: =B14+1 -> 13 | C15: =CONCATENATE("0x",DEC2HEX(B15,4)) -> 0x000D | D15: =CONCATENATE(A15," (",C15,")") -> reg_legal_tx_mode2 (0x000D) | E15: Read/Write | F15: 000D | G15: =CONCATENATE("0x",F15) -> 0x000D | X15: =CONCATENATE("const static uint16_t c_Mil1553_w",A15, " = ",C15,";") -> const static uint16_t c_Mil1553_wreg_legal_tx_mode2 = 0x000D; | Y15: =CONCATENATE(A15," <= X""",F15,""";") -> reg_legal_tx_mode2 <= X"000D"; | Z15: =CONCATENATE(" when X""",C15,""" => DataOut <= ",A15,";") -> when X"0x000D" => DataOut <= reg_legal_tx_mode2; | AA15: =CONCATENATE(" when X""",C15,""" => ",A15," <= DataIn;") -> when X"0x000D" => reg_legal_tx_mode2 <= DataIn;
A16: reg_legal_brdcst_mode1 | B16: =B15+1 -> 14 | C16: =CONCATENATE("0x",DEC2HEX(B16,4)) -> 0x000E | D16: =CONCATENATE(A16," (",C16,")") -> reg_legal_brdcst_mode1 (0x000E) | E16: Read/Write | F16: 01FA | G16: =CONCATENATE("0x",F16) -> 0x01FA | X16: =CONCATENATE("const static uint16_t c_Mil1553_w",A16, " = ",C16,";") -> const static uint16_t c_Mil1553_wreg_legal_brdcst_mode1 = 0x000E; | Y16: =CONCATENATE(A16," <= X""",F16,""";") -> reg_legal_brdcst_mode1 <= X"01FA"; | Z16: =CONCATENATE(" when X""",C16,""" => DataOut <= ",A16,";") -> when X"0x000E" => DataOut <= reg_legal_brdcst_mode1; | AA16: =CONCATENATE(" when X""",C16,""" => ",A16," <= DataIn;") -> when X"0x000E" => reg_legal_brdcst_mode1 <= DataIn;
A17: reg_legal_brdcst_mode2 | B17: =B16+1 -> 15 | C17: =CONCATENATE("0x",DEC2HEX(B17,4)) -> 0x000F | D17: =CONCATENATE(A17," (",C17,")") -> reg_legal_brdcst_mode2 (0x000F) | E17: Read/Write | F17: 0032 | G17: =CONCATENATE("0x",F17) -> 0x0032 | X17: =CONCATENATE("const static uint16_t c_Mil1553_w",A17, " = ",C17,";") -> const static uint16_t c_Mil1553_wreg_legal_brdcst_mode2 = 0x000F; | Y17: =CONCATENATE(A17," <= X""",F17,""";") -> reg_legal_brdcst_mode2 <= X"0032"; | Z17: =CONCATENATE(" when X""",C17,""" => DataOut <= ",A17,";") -> when X"0x000F" => DataOut <= reg_legal_brdcst_mode2; | AA17: =CONCATENATE(" when X""",C17,""" => ",A17," <= DataIn;") -> when X"0x000F" => reg_legal_brdcst_mode2 <= DataIn;
A18: reg_status_rxed1 | B18: 16 | C18: =CONCATENATE("0x",DEC2HEX(B18,4)) -> 0x0010 | D18: =CONCATENATE(A18," (",C18,")") -> reg_status_rxed1 (0x0010) | E18: Read | F18: 0000 | G18: =CONCATENATE("0x",F18) -> 0x0000 | H18: RtAddr4 | I18: RtAddr3 | J18: RTAddr2 | K18: RtAddr1 | L18: RtAddr0 | M18: MessageError | N18: Instrument | O18: ServiceReq | P18: RTAddrError | Q18: Reserved | R18: Reserved | S18: Brdcst Rxes | T18: Busy | U18: SubSysFlag | V18: DBC Acpt | W18: TerminalFlag | X18: =CONCATENATE("const static uint16_t c_Mil1553_w",A18, " = ",C18,";") -> const static uint16_t c_Mil1553_wreg_status_rxed1 = 0x0010; | Y18: =CONCATENATE(A18," <= X""",F18,""";") -> reg_status_rxed1 <= X"0000"; | Z18: =CONCATENATE(" when X""",C18,""" => DataOut <= ",A18,";") -> when X"0x0010" => DataOut <= reg_status_rxed1; | AA18: =CONCATENATE(" when X""",C18,""" => ",A18," <= DataIn;") -> when X"0x0010" => reg_status_rxed1 <= DataIn;
A19: reg_mode_cmd_rxed1 | B19: =B18+1 -> 17 | C19: =CONCATENATE("0x",DEC2HEX(B19,4)) -> 0x0011 | D19: =CONCATENATE(A19," (",C19,")") -> reg_mode_cmd_rxed1 (0x0011) | E19: Read | F19: 0000 | G19: =CONCATENATE("0x",F19) -> 0x0000 | X19: =CONCATENATE("const static uint16_t c_Mil1553_w",A19, " = ",C19,";") -> const static uint16_t c_Mil1553_wreg_mode_cmd_rxed1 = 0x0011; | Y19: =CONCATENATE(A19," <= X""",F19,""";") -> reg_mode_cmd_rxed1 <= X"0000"; | Z19: =CONCATENATE(" when X""",C19,""" => DataOut <= ",A19,";") -> when X"0x0011" => DataOut <= reg_mode_cmd_rxed1; | AA19: =CONCATENATE(" when X""",C19,""" => ",A19," <= DataIn;") -> when X"0x0011" => reg_mode_cmd_rxed1 <= DataIn;
A20: reg_mode_data_rxed1 | B20: =B19+1 -> 18 | C20: =CONCATENATE("0x",DEC2HEX(B20,4)) -> 0x0012 | D20: =CONCATENATE(A20," (",C20,")") -> reg_mode_data_rxed1 (0x0012) | E20: Read | F20: 0000 | G20: =CONCATENATE("0x",F20) -> 0x0000 | X20: =CONCATENATE("const static uint16_t c_Mil1553_w",A20, " = ",C20,";") -> const static uint16_t c_Mil1553_wreg_mode_data_rxed1 = 0x0012; | Y20: =CONCATENATE(A20," <= X""",F20,""";") -> reg_mode_data_rxed1 <= X"0000"; | Z20: =CONCATENATE(" when X""",C20,""" => DataOut <= ",A20,";") -> when X"0x0012" => DataOut <= reg_mode_data_rxed1; | AA20: =CONCATENATE(" when X""",C20,""" => ",A20," <= DataIn;") -> when X"0x0012" => reg_mode_data_rxed1 <= DataIn;
A21: reg_rx_cmd1 | B21: =B20+1 -> 19 | C21: =CONCATENATE("0x",DEC2HEX(B21,4)) -> 0x0013 | D21: =CONCATENATE(A21," (",C21,")") -> reg_rx_cmd1 (0x0013) | E21: Read | F21: 0000 | G21: =CONCATENATE("0x",F21) -> 0x0000 | K21: OtherTxOff | L21: Inhibit T/F | M21: DBC_accepted | N21: Synchronize | O21: InitiateBIT | X21: =CONCATENATE("const static uint16_t c_Mil1553_w",A21, " = ",C21,";") -> const static uint16_t c_Mil1553_wreg_rx_cmd1 = 0x0013; | Y21: =CONCATENATE(A21," <= X""",F21,""";") -> reg_rx_cmd1 <= X"0000"; | Z21: =CONCATENATE(" when X""",C21,""" => DataOut <= ",A21,";") -> when X"0x0013" => DataOut <= reg_rx_cmd1; | AA21: =CONCATENATE(" when X""",C21,""" => ",A21," <= DataIn;") -> when X"0x0013" => reg_rx_cmd1 <= DataIn;
A22: reg_tx_control1 | B22: =B21+1 -> 20 | C22: =CONCATENATE("0x",DEC2HEX(B22,4)) -> 0x0014 | D22: =CONCATENATE(A22," (",C22,")") -> reg_tx_control1 (0x0014) | E22: Read/Write | F22: 0000 | G22: =CONCATENATE("0x",F22) -> 0x0000 | H22: RT2RT | I22: SendMessage | X22: =CONCATENATE("const static uint16_t c_Mil1553_w",A22, " = ",C22,";") -> const static uint16_t c_Mil1553_wreg_tx_control1 = 0x0014; | Y22: =CONCATENATE(A22," <= X""",F22,""";") -> reg_tx_control1 <= X"0000"; | Z22: =CONCATENATE(" when X""",C22,""" => DataOut <= ",A22,";") -> when X"0x0014" => DataOut <= reg_tx_control1; | AA22: =CONCATENATE(" when X""",C22,""" => ",A22," <= DataIn;") -> when X"0x0014" => reg_tx_control1 <= DataIn;
A23: reg_cmd_proc_start1 | B23: =B22+1 -> 21 | C23: =CONCATENATE("0x",DEC2HEX(B23,4)) -> 0x0015 | D23: =CONCATENATE(A23," (",C23,")") -> reg_cmd_proc_start1 (0x0015) | E23: Read/Write | F23: 0000 | G23: =CONCATENATE("0x",F23) -> 0x0000 | X23: =CONCATENATE("const static uint16_t c_Mil1553_w",A23, " = ",C23,";") -> const static uint16_t c_Mil1553_wreg_cmd_proc_start1 = 0x0015; | Y23: =CONCATENATE(A23," <= X""",F23,""";") -> reg_cmd_proc_start1 <= X"0000"; | Z23: =CONCATENATE(" when X""",C23,""" => DataOut <= ",A23,";") -> when X"0x0015" => DataOut <= reg_cmd_proc_start1; | AA23: =CONCATENATE(" when X""",C23,""" => ",A23," <= DataIn;") -> when X"0x0015" => reg_cmd_proc_start1 <= DataIn;
A24: reg_cmd_proc_length1 | B24: =B23+1 -> 22 | C24: =CONCATENATE("0x",DEC2HEX(B24,4)) -> 0x0016 | D24: =CONCATENATE(A24," (",C24,")") -> reg_cmd_proc_length1 (0x0016) | E24: Read/Write | F24: 0000 | G24: =CONCATENATE("0x",F24) -> 0x0000 | X24: =CONCATENATE("const static uint16_t c_Mil1553_w",A24, " = ",C24,";") -> const static uint16_t c_Mil1553_wreg_cmd_proc_length1 = 0x0016; | Y24: =CONCATENATE(A24," <= X""",F24,""";") -> reg_cmd_proc_length1 <= X"0000"; | Z24: =CONCATENATE(" when X""",C24,""" => DataOut <= ",A24,";") -> when X"0x0016" => DataOut <= reg_cmd_proc_length1; | AA24: =CONCATENATE(" when X""",C24,""" => ",A24," <= DataIn;") -> when X"0x0016" => reg_cmd_proc_length1 <= DataIn;
A25: reg_cmd_rxed1 | B25: =B24+1 -> 23 | C25: =CONCATENATE("0x",DEC2HEX(B25,4)) -> 0x0017 | D25: =CONCATENATE(A25," (",C25,")") -> reg_cmd_rxed1 (0x0017) | F25: 0000 | G25: =CONCATENATE("0x",F25) -> 0x0000 | H25: RtAddr4 | I25: RtAddr3 | J25: RTAddr2 | K25: RtAddr1 | L25: RtAddr0 | M25: TxnRx | N25: SubAddr4 | O25: SubAddr3 | P25: SubAddr2 | Q25: SubAddr1 | R25: SubAddr0 | S25: DataLen4 | T25: DataLen3 | U25: DataLen2 | V25: DataLen1 | W25: DataLen0 | X25: =CONCATENATE("const static uint16_t c_Mil1553_w",A25, " = ",C25,";") -> const static uint16_t c_Mil1553_wreg_cmd_rxed1 = 0x0017; | Y25: =CONCATENATE(A25," <= X""",F25,""";") -> reg_cmd_rxed1 <= X"0000"; | Z25: =CONCATENATE(" when X""",C25,""" => DataOut <= ",A25,";") -> when X"0x0017" => DataOut <= reg_cmd_rxed1; | AA25: =CONCATENATE(" when X""",C25,""" => ",A25," <= DataIn;") -> when X"0x0017" => reg_cmd_rxed1 <= DataIn;
A26: reg_24 | B26: =B25+1 -> 24 | C26: =CONCATENATE("0x",DEC2HEX(B26,4)) -> 0x0018 | D26: =CONCATENATE(A26," (",C26,")") -> reg_24 (0x0018) | F26: 0000 | G26: =CONCATENATE("0x",F26) -> 0x0000 | X26: =CONCATENATE("const static uint16_t c_Mil1553_w",A26, " = ",C26,";") -> const static uint16_t c_Mil1553_wreg_24 = 0x0018; | Y26: =CONCATENATE(A26," <= X""",F26,""";") -> reg_24 <= X"0000"; | Z26: =CONCATENATE(" when X""",C26,""" => DataOut <= ",A26,";") -> when X"0x0018" => DataOut <= reg_24; | AA26: =CONCATENATE(" when X""",C26,""" => ",A26," <= DataIn;") -> when X"0x0018" => reg_24 <= DataIn;
A27: reg_bus1_DatSyncErr | B27: =B26+1 -> 25 | C27: =CONCATENATE("0x",DEC2HEX(B27,4)) -> 0x0019 | D27: =CONCATENATE(A27," (",C27,")") -> reg_bus1_DatSyncErr (0x0019) | F27: 0000 | G27: =CONCATENATE("0x",F27) -> 0x0000 | X27: =CONCATENATE("const static uint16_t c_Mil1553_w",A27, " = ",C27,";") -> const static uint16_t c_Mil1553_wreg_bus1_DatSyncErr = 0x0019; | Y27: =CONCATENATE(A27," <= X""",F27,""";") -> reg_bus1_DatSyncErr <= X"0000"; | Z27: =CONCATENATE(" when X""",C27,""" => DataOut <= ",A27,";") -> when X"0x0019" => DataOut <= reg_bus1_DatSyncErr; | AA27: =CONCATENATE(" when X""",C27,""" => ",A27," <= DataIn;") -> when X"0x0019" => reg_bus1_DatSyncErr <= DataIn;
A28: reg_bus1_CmdSyncErr | B28: =B27+1 -> 26 | C28: =CONCATENATE("0x",DEC2HEX(B28,4)) -> 0x001A | D28: =CONCATENATE(A28," (",C28,")") -> reg_bus1_CmdSyncErr (0x001A) | F28: 0000 | G28: =CONCATENATE("0x",F28) -> 0x0000 | X28: =CONCATENATE("const static uint16_t c_Mil1553_w",A28, " = ",C28,";") -> const static uint16_t c_Mil1553_wreg_bus1_CmdSyncErr = 0x001A; | Y28: =CONCATENATE(A28," <= X""",F28,""";") -> reg_bus1_CmdSyncErr <= X"0000"; | Z28: =CONCATENATE(" when X""",C28,""" => DataOut <= ",A28,";") -> when X"0x001A" => DataOut <= reg_bus1_CmdSyncErr; | AA28: =CONCATENATE(" when X""",C28,""" => ",A28," <= DataIn;") -> when X"0x001A" => reg_bus1_CmdSyncErr <= DataIn;
A29: reg_bus1_EarlyEdgeErr | B29: =B28+1 -> 27 | C29: =CONCATENATE("0x",DEC2HEX(B29,4)) -> 0x001B | D29: =CONCATENATE(A29," (",C29,")") -> reg_bus1_EarlyEdgeErr (0x001B) | F29: 0000 | G29: =CONCATENATE("0x",F29) -> 0x0000 | X29: =CONCATENATE("const static uint16_t c_Mil1553_w",A29, " = ",C29,";") -> const static uint16_t c_Mil1553_wreg_bus1_EarlyEdgeErr = 0x001B; | Y29: =CONCATENATE(A29," <= X""",F29,""";") -> reg_bus1_EarlyEdgeErr <= X"0000"; | Z29: =CONCATENATE(" when X""",C29,""" => DataOut <= ",A29,";") -> when X"0x001B" => DataOut <= reg_bus1_EarlyEdgeErr; | AA29: =CONCATENATE(" when X""",C29,""" => ",A29," <= DataIn;") -> when X"0x001B" => reg_bus1_EarlyEdgeErr <= DataIn;
A30: reg_bus1_LateEdgeErr | B30: =B29+1 -> 28 | C30: =CONCATENATE("0x",DEC2HEX(B30,4)) -> 0x001C | D30: =CONCATENATE(A30," (",C30,")") -> reg_bus1_LateEdgeErr (0x001C) | F30: 0000 | G30: =CONCATENATE("0x",F30) -> 0x0000 | X30: =CONCATENATE("const static uint16_t c_Mil1553_w",A30, " = ",C30,";") -> const static uint16_t c_Mil1553_wreg_bus1_LateEdgeErr = 0x001C; | Y30: =CONCATENATE(A30," <= X""",F30,""";") -> reg_bus1_LateEdgeErr <= X"0000"; | Z30: =CONCATENATE(" when X""",C30,""" => DataOut <= ",A30,";") -> when X"0x001C" => DataOut <= reg_bus1_LateEdgeErr; | AA30: =CONCATENATE(" when X""",C30,""" => ",A30," <= DataIn;") -> when X"0x001C" => reg_bus1_LateEdgeErr <= DataIn;
A31: reg_bus1_ParityErr | B31: =B30+1 -> 29 | C31: =CONCATENATE("0x",DEC2HEX(B31,4)) -> 0x001D | D31: =CONCATENATE(A31," (",C31,")") -> reg_bus1_ParityErr (0x001D) | F31: 0000 | G31: =CONCATENATE("0x",F31) -> 0x0000 | X31: =CONCATENATE("const static uint16_t c_Mil1553_w",A31, " = ",C31,";") -> const static uint16_t c_Mil1553_wreg_bus1_ParityErr = 0x001D; | Y31: =CONCATENATE(A31," <= X""",F31,""";") -> reg_bus1_ParityErr <= X"0000"; | Z31: =CONCATENATE(" when X""",C31,""" => DataOut <= ",A31,";") -> when X"0x001D" => DataOut <= reg_bus1_ParityErr; | AA31: =CONCATENATE(" when X""",C31,""" => ",A31," <= DataIn;") -> when X"0x001D" => reg_bus1_ParityErr <= DataIn;
A32: reg_bus1_status | B32: =B31+1 -> 30 | C32: =CONCATENATE("0x",DEC2HEX(B32,4)) -> 0x001E | D32: =CONCATENATE(A32," (",C32,")") -> reg_bus1_status (0x001E) | F32: 0000 | G32: =CONCATENATE("0x",F32) -> 0x0000 | P32: ModeCmd | Q32: DataReq | R32: DataReceived | S32: StatusRxedFlag | T32: SAF | U32: REP | V32: NRP | W32: GAP | X32: =CONCATENATE("const static uint16_t c_Mil1553_w",A32, " = ",C32,";") -> const static uint16_t c_Mil1553_wreg_bus1_status = 0x001E; | Y32: =CONCATENATE(A32," <= X""",F32,""";") -> reg_bus1_status <= X"0000"; | Z32: =CONCATENATE(" when X""",C32,""" => DataOut <= ",A32,";") -> when X"0x001E" => DataOut <= reg_bus1_status; | AA32: =CONCATENATE(" when X""",C32,""" => ",A32," <= DataIn;") -> when X"0x001E" => reg_bus1_status <= DataIn;
A33: reg_bus1_mask | B33: =B32+1 -> 31 | C33: =CONCATENATE("0x",DEC2HEX(B33,4)) -> 0x001F | D33: =CONCATENATE(A33," (",C33,")") -> reg_bus1_mask (0x001F) | F33: 0000 | G33: =CONCATENATE("0x",F33) -> 0x0000 | P33: ModeCmd | Q33: DataReq | R33: DataReceived | S33: StatusRxedFlag | T33: SAF | U33: REP | V33: NRP | W33: GAP | X33: =CONCATENATE("const static uint16_t c_Mil1553_w",A33, " = ",C33,";") -> const static uint16_t c_Mil1553_wreg_bus1_mask = 0x001F; | Y33: =CONCATENATE(A33," <= X""",F33,""";") -> reg_bus1_mask <= X"0000"; | Z33: =CONCATENATE(" when X""",C33,""" => DataOut <= ",A33,";") -> when X"0x001F" => DataOut <= reg_bus1_mask; | AA33: =CONCATENATE(" when X""",C33,""" => ",A33," <= DataIn;") -> when X"0x001F" => reg_bus1_mask <= DataIn;
A34: reg_status_rxed2 | B34: 32 | C34: =CONCATENATE("0x",DEC2HEX(B34,4)) -> 0x0020 | D34: =CONCATENATE(A34," (",C34,")") -> reg_status_rxed2 (0x0020) | E34: Read | F34: 0000 | G34: =CONCATENATE("0x",F34) -> 0x0000 | H34: RtAddr4 | I34: RtAddr3 | J34: RTAddr2 | K34: RtAddr1 | L34: RtAddr0 | M34: MessageError | N34: Instrument | O34: ServiceReq | P34: RTAddrError | Q34: Reserved | R34: Reserved | S34: Brdcst Rxes | T34: Busy | U34: SubSysFlag | V34: DBC Acpt | W34: TerminalFlag | X34: =CONCATENATE("const static uint16_t c_Mil1553_w",A34, " = ",C34,";") -> const static uint16_t c_Mil1553_wreg_status_rxed2 = 0x0020; | Y34: =CONCATENATE(A34," <= X""",F34,""";") -> reg_status_rxed2 <= X"0000"; | Z34: =CONCATENATE(" when X""",C34,""" => DataOut <= ",A34,";") -> when X"0x0020" => DataOut <= reg_status_rxed2; | AA34: =CONCATENATE(" when X""",C34,""" => ",A34," <= DataIn;") -> when X"0x0020" => reg_status_rxed2 <= DataIn;
A35: reg_mode_cmd_rxed2 | B35: =B34+1 -> 33 | C35: =CONCATENATE("0x",DEC2HEX(B35,4)) -> 0x0021 | D35: =CONCATENATE(A35," (",C35,")") -> reg_mode_cmd_rxed2 (0x0021) | E35: Read | F35: 0000 | G35: =CONCATENATE("0x",F35) -> 0x0000 | X35: =CONCATENATE("const static uint16_t c_Mil1553_w",A35, " = ",C35,";") -> const static uint16_t c_Mil1553_wreg_mode_cmd_rxed2 = 0x0021; | Y35: =CONCATENATE(A35," <= X""",F35,""";") -> reg_mode_cmd_rxed2 <= X"0000"; | Z35: =CONCATENATE(" when X""",C35,""" => DataOut <= ",A35,";") -> when X"0x0021" => DataOut <= reg_mode_cmd_rxed2; | AA35: =CONCATENATE(" when X""",C35,""" => ",A35," <= DataIn;") -> when X"0x0021" => reg_mode_cmd_rxed2 <= DataIn;
A36: reg_mode_data_rxed2 | B36: =B35+1 -> 34 | C36: =CONCATENATE("0x",DEC2HEX(B36,4)) -> 0x0022 | D36: =CONCATENATE(A36," (",C36,")") -> reg_mode_data_rxed2 (0x0022) | E36: Read | F36: 0000 | G36: =CONCATENATE("0x",F36) -> 0x0000 | X36: =CONCATENATE("const static uint16_t c_Mil1553_w",A36, " = ",C36,";") -> const static uint16_t c_Mil1553_wreg_mode_data_rxed2 = 0x0022; | Y36: =CONCATENATE(A36," <= X""",F36,""";") -> reg_mode_data_rxed2 <= X"0000"; | Z36: =CONCATENATE(" when X""",C36,""" => DataOut <= ",A36,";") -> when X"0x0022" => DataOut <= reg_mode_data_rxed2; | AA36: =CONCATENATE(" when X""",C36,""" => ",A36," <= DataIn;") -> when X"0x0022" => reg_mode_data_rxed2 <= DataIn;
A37: reg_rx_cmd2 | B37: =B36+1 -> 35 | C37: =CONCATENATE("0x",DEC2HEX(B37,4)) -> 0x0023 | D37: =CONCATENATE(A37," (",C37,")") -> reg_rx_cmd2 (0x0023) | E37: Read | F37: 0000 | G37: =CONCATENATE("0x",F37) -> 0x0000 | K37: OtherTxOff | L37: Inhibit T/F | M37: DBC_accepted | N37: Synchronize | O37: InitiateBIT | X37: =CONCATENATE("const static uint16_t c_Mil1553_w",A37, " = ",C37,";") -> const static uint16_t c_Mil1553_wreg_rx_cmd2 = 0x0023; | Y37: =CONCATENATE(A37," <= X""",F37,""";") -> reg_rx_cmd2 <= X"0000"; | Z37: =CONCATENATE(" when X""",C37,""" => DataOut <= ",A37,";") -> when X"0x0023" => DataOut <= reg_rx_cmd2; | AA37: =CONCATENATE(" when X""",C37,""" => ",A37," <= DataIn;") -> when X"0x0023" => reg_rx_cmd2 <= DataIn;
A38: reg_tx_control2 | B38: =B37+1 -> 36 | C38: =CONCATENATE("0x",DEC2HEX(B38,4)) -> 0x0024 | D38: =CONCATENATE(A38," (",C38,")") -> reg_tx_control2 (0x0024) | E38: Read/Write | F38: 0000 | G38: =CONCATENATE("0x",F38) -> 0x0000 | H38: RT2RT | I38: SendMessage | X38: =CONCATENATE("const static uint16_t c_Mil1553_w",A38, " = ",C38,";") -> const static uint16_t c_Mil1553_wreg_tx_control2 = 0x0024; | Y38: =CONCATENATE(A38," <= X""",F38,""";") -> reg_tx_control2 <= X"0000"; | Z38: =CONCATENATE(" when X""",C38,""" => DataOut <= ",A38,";") -> when X"0x0024" => DataOut <= reg_tx_control2; | AA38: =CONCATENATE(" when X""",C38,""" => ",A38," <= DataIn;") -> when X"0x0024" => reg_tx_control2 <= DataIn;
A39: reg_cmd_proc_start2 | B39: =B38+1 -> 37 | C39: =CONCATENATE("0x",DEC2HEX(B39,4)) -> 0x0025 | D39: =CONCATENATE(A39," (",C39,")") -> reg_cmd_proc_start2 (0x0025) | E39: Read/Write | F39: 0000 | G39: =CONCATENATE("0x",F39) -> 0x0000 | X39: =CONCATENATE("const static uint16_t c_Mil1553_w",A39, " = ",C39,";") -> const static uint16_t c_Mil1553_wreg_cmd_proc_start2 = 0x0025; | Y39: =CONCATENATE(A39," <= X""",F39,""";") -> reg_cmd_proc_start2 <= X"0000"; | Z39: =CONCATENATE(" when X""",C39,""" => DataOut <= ",A39,";") -> when X"0x0025" => DataOut <= reg_cmd_proc_start2; | AA39: =CONCATENATE(" when X""",C39,""" => ",A39," <= DataIn;") -> when X"0x0025" => reg_cmd_proc_start2 <= DataIn;
A40: reg_cmd_proc_length2 | B40: =B39+1 -> 38 | C40: =CONCATENATE("0x",DEC2HEX(B40,4)) -> 0x0026 | D40: =CONCATENATE(A40," (",C40,")") -> reg_cmd_proc_length2 (0x0026) | E40: Read/Write | F40: 0000 | G40: =CONCATENATE("0x",F40) -> 0x0000 | X40: =CONCATENATE("const static uint16_t c_Mil1553_w",A40, " = ",C40,";") -> const static uint16_t c_Mil1553_wreg_cmd_proc_length2 = 0x0026; | Y40: =CONCATENATE(A40," <= X""",F40,""";") -> reg_cmd_proc_length2 <= X"0000"; | Z40: =CONCATENATE(" when X""",C40,""" => DataOut <= ",A40,";") -> when X"0x0026" => DataOut <= reg_cmd_proc_length2; | AA40: =CONCATENATE(" when X""",C40,""" => ",A40," <= DataIn;") -> when X"0x0026" => reg_cmd_proc_length2 <= DataIn;
...

Sheet FAT Result Sheet
A1: TEST 1
A2: UUT/RT
B3: Expected | C3: Received
A4: Converter Software Version | B4: N/A
A5: Converter Firmware version | B5: N/A
A6: UART1 Firmware Version | B6: N/A
A7: UART2 Firmware Version | B7: N/A
A8: MIL1553 Core Firmware Version | B8: N/A
A9: UUT
B10: Expected | C10: Received
A11: Converter Software Version | B11: N/A
A12: Converter Firmware version | B12: N/A
A13: UART1 Firmware Version | B13: N/A
A14: UART2 Firmware Version | B14: N/A
A15: MIL1553 Core Firmware Version | B15: N/A
A17: TEST 2
A18: ADDR = 00000
A19: Description | B19: Expected | C19: Received | D19: Pass/Fail
A20: Address on BC | B20: 00000
A21: Parity on BC | B21: 1
A22: Address on RT | B22: 00000
A23: Parity on RT | B23: 1
A24: ADDR = 11111
A25: Description | B25: Expected | C25: Received | D25: Pass/Fail
A26: Address on BC | B26: 11111
A27: Parity on BC | B27: 0
A28: Address on RT | B28: 11111
A29: Parity on RT | B29: 0
A30: ADDR = 10101
A31: Description | B31: Expected | C31: Received | D31: Pass/Fail
A32: Address on BC | B32: 10101
A33: Parity on BC | B33: 0
A34: Address on RT | B34: 10101
A35: Parity on RT | B35: 0
A36: ADDR = 01010
A37: Description | B37: Expected | C37: Received | D37: Pass/Fail
A38: Address on BC | B38: 01010
A39: Parity on BC | B39: 1
A40: Address on RT | B40: 01010
A41: Parity on RT | B41: 1

Sheet CONV_USB_1553_Registers
A1: Registers | B1: Add | C1: Address | E1: Read/Write | F1: Default | G1: Default | H1: 15 | I1: 14 | J1: 13 | K1: 12 | L1: 11 | M1: 10 | N1: 9 | O1: 8 | P1: 7 | Q1: 6 | R1: 5 | S1: 4 | T1: 3 | U1: 2 | V1: 1 | W1: 0 | X1: Register deifnitions | Y1: Reset Assignment | Z1: RD command | AA1: Wr Command | AB1: PORT
A2: reg_status | B2: 0 | C2: =CONCATENATE("0x",DEC2HEX(B2,4)) -> 0x0000 | D2: =CONCATENATE(A2," (",C2,")") -> reg_status (0x0000) | E2: Read | F2: 0000 | G2: =CONCATENATE("0x",F2) -> 0x0000 | L2: TX EMPTY | M2: RX MSG | N2: 28V1 | O2: 28V2 | P2: INT | Q2: REL | X2: =CONCATENATE("const static uint16_t c_w",A2, " = ",C2,";") -> const static uint16_t c_wreg_status = 0x0000; | Y2: =IF(E2<>"READ",CONCATENATE(A2," <= X""",F2,""";"),"") | Z2: =IF(E2<>"WRITE",CONCATENATE(" when X""",C2,""" => DataOut <= ",A2,";"),"") -> when X"0x0000" => DataOut <= reg_status; | AA2: =IF(E2<>"READ",CONCATENATE(" when X""",C2,""" => ",A2," <= DataIn;"),"") | AB2: =IF(E2<>"READ",CONCATENATE(A2," : BUFFER std_logic_vector (15 DOWNTO 0);"),CONCATENATE(A2," : IN std_logic_vector (15 DOWNTO 0);")) -> reg_status : IN std_logic_vector (15 DOWNTO 0); | AC2: =CONCATENATE("pl1553BaseAddress[c_w",A2, "] = 0x",F2,";") -> pl1553BaseAddress[c_wreg_status] = 0x0000;
A3: reg_intr_mask | B3: =B2+1 -> 1 | C3: =CONCATENATE("0x",DEC2HEX(B3,4)) -> 0x0001 | D3: =CONCATENATE(A3," (",C3,")") -> reg_intr_mask (0x0001) | E3: Read/Write | F3: 0000 | G3: =CONCATENATE("0x",F3) -> 0x0000 | L3: TX EMPTY | M3: RX MSG | N3: 28V1 | O3: 28V2 | P3: INT | Q3: REL | X3: =CONCATENATE("const static uint16_t c_w",A3, " = ",C3,";") -> const static uint16_t c_wreg_intr_mask = 0x0001; | Y3: =IF(E3<>"READ",CONCATENATE(A3," <= X""",F3,""";"),"") -> reg_intr_mask <= X"0000"; | Z3: =IF(E3<>"WRITE",CONCATENATE(" when X""",C3,""" => DataOut <= ",A3,";"),"") -> when X"0x0001" => DataOut <= reg_intr_mask; | AA3: =IF(E3<>"READ",CONCATENATE(" when X""",C3,""" => ",A3," <= DataIn;"),"") -> when X"0x0001" => reg_intr_mask <= DataIn; | AB3: =IF(E3<>"READ",CONCATENATE(A3," : BUFFER std_logic_vector (15 DOWNTO 0);"),CONCATENATE(A3," : IN std_logic_vector (15 DOWNTO 0);")) -> reg_intr_mask : BUFFER std_logic_vector (15 DOWNTO 0); | AC3: =CONCATENATE("pl1553BaseAddress[c_w",A3, "] = 0x",F3,";") -> pl1553BaseAddress[c_wreg_intr_mask] = 0x0000;
A4: reg_gID | B4: =B3+1 -> 2 | C4: =CONCATENATE("0x",DEC2HEX(B4,4)) -> 0x0002 | D4: =CONCATENATE(A4," (",C4,")") -> reg_gID (0x0002) | E4: Read/Write | F4: BEEF | G4: =CONCATENATE("0x",F4) -> 0xBEEF | H4: 1 | I4: 0 | J4: 1 | K4: 1 | L4: 1 | M4: 1 | N4: 1 | O4: 0 | P4: 1 | Q4: 1 | R4: 1 | S4: 0 | T4: 1 | U4: 1 | V4: 1 | W4: 1 | X4: =CONCATENATE("const static uint16_t c_w",A4, " = ",C4,";") -> const static uint16_t c_wreg_gID = 0x0002; | Y4: =IF(E4<>"READ",CONCATENATE(A4," <= X""",F4,""";"),"") -> reg_gID <= X"BEEF"; | Z4: =IF(E4<>"WRITE",CONCATENATE(" when X""",C4,""" => DataOut <= ",A4,";"),"") -> when X"0x0002" => DataOut <= reg_gID; | AA4: =IF(E4<>"READ",CONCATENATE(" when X""",C4,""" => ",A4," <= DataIn;"),"") -> when X"0x0002" => reg_gID <= DataIn; | AB4: =IF(E4<>"READ",CONCATENATE(A4," : BUFFER std_logic_vector (15 DOWNTO 0);"),CONCATENATE(A4," : IN std_logic_vector (15 DOWNTO 0);")) -> reg_gID : BUFFER std_logic_vector (15 DOWNTO 0); | AC4: =CONCATENATE("pl1553BaseAddress[c_w",A4, "] = 0x",F4,";") -> pl1553BaseAddress[c_wreg_gID] = 0xBEEF;
A5: reg_fw_version | B5: =B4+1 -> 3 | C5: =CONCATENATE("0x",DEC2HEX(B5,4)) -> 0x0003 | D5: =CONCATENATE(A5," (",C5,")") -> reg_fw_version (0x0003) | E5: Read | F5: 0100 | G5: =CONCATENATE("0x",F5) -> 0x0100 | H5: 0 | I5: 0 | J5: 0 | K5: 0 | L5: 0 | M5: 0 | N5: 0 | O5: 1 | P5: 0 | Q5: 0 | R5: 0 | S5: 0 | T5: 0 | U5: 0 | V5: 0 | W5: 0 | X5: =CONCATENATE("const static uint16_t c_w",A5, " = ",C5,";") -> const static uint16_t c_wreg_fw_version = 0x0003; | Y5: =IF(E5<>"READ",CONCATENATE(A5," <= X""",F5,""";"),"") | Z5: =IF(E5<>"WRITE",CONCATENATE(" when X""",C5,""" => DataOut <= ",A5,";"),"") -> when X"0x0003" => DataOut <= reg_fw_version; | AA5: =IF(E5<>"READ",CONCATENATE(" when X""",C5,""" => ",A5," <= DataIn;"),"") | AB5: =IF(E5<>"READ",CONCATENATE(A5," : BUFFER std_logic_vector (15 DOWNTO 0);"),CONCATENATE(A5," : IN std_logic_vector (15 DOWNTO 0);")) -> reg_fw_version : IN std_logic_vector (15 DOWNTO 0); | AC5: =CONCATENATE("pl1553BaseAddress[c_w",A5, "] = 0x",F5,";") -> pl1553BaseAddress[c_wreg_fw_version] = 0x0100;
A6: reg_mode_addr_wr | B6: =B5+1 -> 4 | C6: =CONCATENATE("0x",DEC2HEX(B6,4)) -> 0x0004 | D6: =CONCATENATE(A6," (",C6,")") -> reg_mode_addr_wr (0x0004) | E6: Read/Write | F6: 0000 | G6: =CONCATENATE("0x",F6) -> 0x0000 | H6: MON | I6: RT | J6: BC | K6: RT Drive | L6: TX EMPTY | M6: RX MSG | N6: 28V1 | O6: 28V2 | P6: INT | Q6: REL | R6: PAR | S6: ADR4 | T6: ADR3 | U6: ADR2 | V6: ADR1 | W6: ADR0 | X6: =CONCATENATE("const static uint16_t c_w",A6, " = ",C6,";") -> const static uint16_t c_wreg_mode_addr_wr = 0x0004; | Y6: =IF(E6<>"READ",CONCATENATE(A6," <= X""",F6,""";"),"") -> reg_mode_addr_wr <= X"0000"; | Z6: =IF(E6<>"WRITE",CONCATENATE(" when X""",C6,""" => DataOut <= ",A6,";"),"") -> when X"0x0004" => DataOut <= reg_mode_addr_wr; | AA6: =IF(E6<>"READ",CONCATENATE(" when X""",C6,""" => ",A6," <= DataIn;"),"") -> when X"0x0004" => reg_mode_addr_wr <= DataIn; | AB6: =IF(E6<>"READ",CONCATENATE(A6," : BUFFER std_logic_vector (15 DOWNTO 0);"),CONCATENATE(A6," : IN std_logic_vector (15 DOWNTO 0);")) -> reg_mode_addr_wr : BUFFER std_logic_vector (15 DOWNTO 0); | AC6: =CONCATENATE("pl1553BaseAddress[c_w",A6, "] = 0x",F6,";") -> pl1553BaseAddress[c_wreg_mode_addr_wr] = 0x0000;
A7: reg_mode_addr_rd | B7: =B6+1 -> 5 | C7: =CONCATENATE("0x",DEC2HEX(B7,4)) -> 0x0005 | D7: =CONCATENATE(A7," (",C7,")") -> reg_mode_addr_rd (0x0005) | E7: Read/Write | F7: 0000 | G7: =CONCATENATE("0x",F7) -> 0x0000 | N7: 28V1 | O7: 28V2 | P7: INT | Q7: REL | R7: PAR | S7: ADR4 | T7: ADR3 | U7: ADR2 | V7: ADR1 | W7: ADR0 | X7: =CONCATENATE("const static uint16_t c_w",A7, " = ",C7,";") -> const static uint16_t c_wreg_mode_addr_rd = 0x0005; | Y7: =IF(E7<>"READ",CONCATENATE(A7," <= X""",F7,""";"),"") -> reg_mode_addr_rd <= X"0000"; | Z7: =IF(E7<>"WRITE",CONCATENATE(" when X""",C7,""" => DataOut <= ",A7,";"),"") -> when X"0x0005" => DataOut <= reg_mode_addr_rd; | AA7: =IF(E7<>"READ",CONCATENATE(" when X""",C7,""" => ",A7," <= DataIn;"),"") -> when X"0x0005" => reg_mode_addr_rd <= DataIn; | AB7: =IF(E7<>"READ",CONCATENATE(A7," : BUFFER std_logic_vector (15 DOWNTO 0);"),CONCATENATE(A7," : IN std_logic_vector (15 DOWNTO 0);")) -> reg_mode_addr_rd : BUFFER std_logic_vector (15 DOWNTO 0); | AC7: =CONCATENATE("pl1553BaseAddress[c_w",A7, "] = 0x",F7,";") -> pl1553BaseAddress[c_wreg_mode_addr_rd] = 0x0000;
A8: reg_control | B8: =B7+1 -> 6 | C8: =CONCATENATE("0x",DEC2HEX(B8,4)) -> 0x0006 | D8: =CONCATENATE(A8," (",C8,")") -> reg_control (0x0006) | E8: Read/Write | F8: 0000 | G8: =CONCATENATE("0x",F8) -> 0x0000 | K8: UseConfigAddr | S8: RstConv | T8: RstMil1553 | U8: RstUart2 | V8: Rst Uart1 | W8: FLASHLEDS | X8: =CONCATENATE("const static uint16_t c_w",A8, " = ",C8,";") -> const static uint16_t c_wreg_control = 0x0006; | Y8: =IF(E8<>"READ",CONCATENATE(A8," <= X""",F8,""";"),"") -> reg_control <= X"0000"; | Z8: =IF(E8<>"WRITE",CONCATENATE(" when X""",C8,""" => DataOut <= ",A8,";"),"") -> when X"0x0006" => DataOut <= reg_control; | AA8: =IF(E8<>"READ",CONCATENATE(" when X""",C8,""" => ",A8," <= DataIn;"),"") -> when X"0x0006" => reg_control <= DataIn; | AB8: =IF(E8<>"READ",CONCATENATE(A8," : BUFFER std_logic_vector (15 DOWNTO 0);"),CONCATENATE(A8," : IN std_logic_vector (15 DOWNTO 0);")) -> reg_control : BUFFER std_logic_vector (15 DOWNTO 0); | AC8: =CONCATENATE("pl1553BaseAddress[c_w",A8, "] = 0x",F8,";") -> pl1553BaseAddress[c_wreg_control] = 0x0000;
A9: reg_sw_version | B9: =B8+1 -> 7 | C9: =CONCATENATE("0x",DEC2HEX(B9,4)) -> 0x0007 | D9: =CONCATENATE(A9," (",C9,")") -> reg_sw_version (0x0007) | E9: Read/Write | F9: 0000 | G9: =CONCATENATE("0x",F9) -> 0x0000 | X9: =CONCATENATE("const static uint16_t c_w",A9, " = ",C9,";") -> const static uint16_t c_wreg_sw_version = 0x0007; | Y9: =IF(E9<>"READ",CONCATENATE(A9," <= X""",F9,""";"),"") -> reg_sw_version <= X"0000"; | Z9: =IF(E9<>"WRITE",CONCATENATE(" when X""",C9,""" => DataOut <= ",A9,";"),"") -> when X"0x0007" => DataOut <= reg_sw_version; | AA9: =IF(E9<>"READ",CONCATENATE(" when X""",C9,""" => ",A9," <= DataIn;"),"") -> when X"0x0007" => reg_sw_version <= DataIn; | AB9: =IF(E9<>"READ",CONCATENATE(A9," : BUFFER std_logic_vector (15 DOWNTO 0);"),CONCATENATE(A9," : IN std_logic_vector (15 DOWNTO 0);")) -> reg_sw_version : BUFFER std_logic_vector (15 DOWNTO 0); | AC9: =CONCATENATE("pl1553BaseAddress[c_w",A9, "] = 0x",F9,";") -> pl1553BaseAddress[c_wreg_sw_version] = 0x0000;
A10: reg_8 | B10: =B9+1 -> 8 | C10: =CONCATENATE("0x",DEC2HEX(B10,4)) -> 0x0008 | D10: =CONCATENATE(A10," (",C10,")") -> reg_8 (0x0008) | E10: Read/Write | F10: 0000 | G10: =CONCATENATE("0x",F10) -> 0x0000 | X10: =CONCATENATE("const static uint16_t c_w",A10, " = ",C10,";") -> const static uint16_t c_wreg_8 = 0x0008; | Y10: =IF(E10<>"READ",CONCATENATE(A10," <= X""",F10,""";"),"") -> reg_8 <= X"0000"; | Z10: =IF(E10<>"WRITE",CONCATENATE(" when X""",C10,""" => DataOut <= ",A10,";"),"") -> when X"0x0008" => DataOut <= reg_8; | AA10: =IF(E10<>"READ",CONCATENATE(" when X""",C10,""" => ",A10," <= DataIn;"),"") -> when X"0x0008" => reg_8 <= DataIn; | AB10: =IF(E10<>"READ",CONCATENATE(A10," : BUFFER std_logic_vector (15 DOWNTO 0);"),CONCATENATE(A10," : IN std_logic_vector (15 DOWNTO 0);")) -> reg_8 : BUFFER std_logic_vector (15 DOWNTO 0); | AC10: =CONCATENATE("pl1553BaseAddress[c_w",A10, "] = 0x",F10,";") -> pl1553BaseAddress[c_wreg_8] = 0x0000;
A11: reg_9 | B11: =B10+1 -> 9 | C11: =CONCATENATE("0x",DEC2HEX(B11,4)) -> 0x0009 | D11: =CONCATENATE(A11," (",C11,")") -> reg_9 (0x0009) | E11: Read/Write | F11: 0000 | G11: =CONCATENATE("0x",F11) -> 0x0000 | X11: =CONCATENATE("const static uint16_t c_w",A11, " = ",C11,";") -> const static uint16_t c_wreg_9 = 0x0009; | Y11: =IF(E11<>"READ",CONCATENATE(A11," <= X""",F11,""";"),"") -> reg_9 <= X"0000"; | Z11: =IF(E11<>"WRITE",CONCATENATE(" when X""",C11,""" => DataOut <= ",A11,";"),"") -> when X"0x0009" => DataOut <= reg_9; | AA11: =IF(E11<>"READ",CONCATENATE(" when X""",C11,""" => ",A11," <= DataIn;"),"") -> when X"0x0009" => reg_9 <= DataIn; | AB11: =IF(E11<>"READ",CONCATENATE(A11," : BUFFER std_logic_vector (15 DOWNTO 0);"),CONCATENATE(A11," : IN std_logic_vector (15 DOWNTO 0);")) -> reg_9 : BUFFER std_logic_vector (15 DOWNTO 0); | AC11: =CONCATENATE("pl1553BaseAddress[c_w",A11, "] = 0x",F11,";") -> pl1553BaseAddress[c_wreg_9] = 0x0000;
A12: reg_10 | B12: =B11+1 -> 10 | C12: =CONCATENATE("0x",DEC2HEX(B12,4)) -> 0x000A | D12: =CONCATENATE(A12," (",C12,")") -> reg_10 (0x000A) | E12: Read/Write | F12: 0000 | G12: =CONCATENATE("0x",F12) -> 0x0000 | X12: =CONCATENATE("const static uint16_t c_w",A12, " = ",C12,";") -> const static uint16_t c_wreg_10 = 0x000A; | Y12: =IF(E12<>"READ",CONCATENATE(A12," <= X""",F12,""";"),"") -> reg_10 <= X"0000"; | Z12: =IF(E12<>"WRITE",CONCATENATE(" when X""",C12,""" => DataOut <= ",A12,";"),"") -> when X"0x000A" => DataOut <= reg_10; | AA12: =IF(E12<>"READ",CONCATENATE(" when X""",C12,""" => ",A12," <= DataIn;"),"") -> when X"0x000A" => reg_10 <= DataIn; | AB12: =IF(E12<>"READ",CONCATENATE(A12," : BUFFER std_logic_vector (15 DOWNTO 0);"),CONCATENATE(A12," : IN std_logic_vector (15 DOWNTO 0);")) -> reg_10 : BUFFER std_logic_vector (15 DOWNTO 0); | AC12: =CONCATENATE("pl1553BaseAddress[c_w",A12, "] = 0x",F12,";") -> pl1553BaseAddress[c_wreg_10] = 0x0000;
A13: reg_11 | B13: =B12+1 -> 11 | C13: =CONCATENATE("0x",DEC2HEX(B13,4)) -> 0x000B | D13: =CONCATENATE(A13," (",C13,")") -> reg_11 (0x000B) | E13: Read/Write | F13: 0000 | G13: =CONCATENATE("0x",F13) -> 0x0000 | X13: =CONCATENATE("const static uint16_t c_w",A13, " = ",C13,";") -> const static uint16_t c_wreg_11 = 0x000B; | Y13: =IF(E13<>"READ",CONCATENATE(A13," <= X""",F13,""";"),"") -> reg_11 <= X"0000"; | Z13: =IF(E13<>"WRITE",CONCATENATE(" when X""",C13,""" => DataOut <= ",A13,";"),"") -> when X"0x000B" => DataOut <= reg_11; | AA13: =IF(E13<>"READ",CONCATENATE(" when X""",C13,""" => ",A13," <= DataIn;"),"") -> when X"0x000B" => reg_11 <= DataIn; | AB13: =IF(E13<>"READ",CONCATENATE(A13," : BUFFER std_logic_vector (15 DOWNTO 0);"),CONCATENATE(A13," : IN std_logic_vector (15 DOWNTO 0);")) -> reg_11 : BUFFER std_logic_vector (15 DOWNTO 0); | AC13: =CONCATENATE("pl1553BaseAddress[c_w",A13, "] = 0x",F13,";") -> pl1553BaseAddress[c_wreg_11] = 0x0000;
A14: Timestamp3_MSB | B14: =B13+1 -> 12 | C14: =CONCATENATE("0x",DEC2HEX(B14,4)) -> 0x000C | D14: =CONCATENATE(A14," (",C14,")") -> Timestamp3_MSB (0x000C) | E14: Read/Write | F14: 0000 | G14: =CONCATENATE("0x",F14) -> 0x0000 | X14: =CONCATENATE("const static uint16_t c_w",A14, " = ",C14,";") -> const static uint16_t c_wTimestamp3_MSB = 0x000C; | Y14: =IF(E14<>"READ",CONCATENATE(A14," <= X""",F14,""";"),"") -> Timestamp3_MSB <= X"0000"; | Z14: =IF(E14<>"WRITE",CONCATENATE(" when X""",C14,""" => DataOut <= ",A14,";"),"") -> when X"0x000C" => DataOut <= Timestamp3_MSB; | AA14: =IF(E14<>"READ",CONCATENATE(" when X""",C14,""" => ",A14," <= DataIn;"),"") -> when X"0x000C" => Timestamp3_MSB <= DataIn; | AB14: =IF(E14<>"READ",CONCATENATE(A14," : BUFFER std_logic_vector (15 DOWNTO 0);"),CONCATENATE(A14," : IN std_logic_vector (15 DOWNTO 0);")) -> Timestamp3_MSB : BUFFER std_logic_vector (15 DOWNTO 0); | AC14: =CONCATENATE("pl1553BaseAddress[c_w",A14, "] = 0x",F14,";") -> pl1553BaseAddress[c_wTimestamp3_MSB] = 0x0000;
A15: Timestamp2 | B15: =B14+1 -> 13 | C15: =CONCATENATE("0x",DEC2HEX(B15,4)) -> 0x000D | D15: =CONCATENATE(A15," (",C15,")") -> Timestamp2 (0x000D) | E15: Read/Write | F15: 0000 | G15: =CONCATENATE("0x",F15) -> 0x0000 | X15: =CONCATENATE("const static uint16_t c_w",A15, " = ",C15,";") -> const static uint16_t c_wTimestamp2 = 0x000D; | Y15: =IF(E15<>"READ",CONCATENATE(A15," <= X""",F15,""";"),"") -> Timestamp2 <= X"0000"; | Z15: =IF(E15<>"WRITE",CONCATENATE(" when X""",C15,""" => DataOut <= ",A15,";"),"") -> when X"0x000D" => DataOut <= Timestamp2; | AA15: =IF(E15<>"READ",CONCATENATE(" when X""",C15,""" => ",A15," <= DataIn;"),"") -> when X"0x000D" => Timestamp2 <= DataIn; | AB15: =IF(E15<>"READ",CONCATENATE(A15," : BUFFER std_logic_vector (15 DOWNTO 0);"),CONCATENATE(A15," : IN std_logic_vector (15 DOWNTO 0);")) -> Timestamp2 : BUFFER std_logic_vector (15 DOWNTO 0); | AC15: =CONCATENATE("pl1553BaseAddress[c_w",A15, "] = 0x",F15,";") -> pl1553BaseAddress[c_wTimestamp2] = 0x0000;
A16: Timestamp1 | B16: =B15+1 -> 14 | C16: =CONCATENATE("0x",DEC2HEX(B16,4)) -> 0x000E | D16: =CONCATENATE(A16," (",C16,")") -> Timestamp1 (0x000E) | E16: Read/Write | F16: 0000 | G16: =CONCATENATE("0x",F16) -> 0x0000 | X16: =CONCATENATE("const static uint16_t c_w",A16, " = ",C16,";") -> const static uint16_t c_wTimestamp1 = 0x000E; | Y16: =IF(E16<>"READ",CONCATENATE(A16," <= X""",F16,""";"),"") -> Timestamp1 <= X"0000"; | Z16: =IF(E16<>"WRITE",CONCATENATE(" when X""",C16,""" => DataOut <= ",A16,";"),"") -> when X"0x000E" => DataOut <= Timestamp1; | AA16: =IF(E16<>"READ",CONCATENATE(" when X""",C16,""" => ",A16," <= DataIn;"),"") -> when X"0x000E" => Timestamp1 <= DataIn; | AB16: =IF(E16<>"READ",CONCATENATE(A16," : BUFFER std_logic_vector (15 DOWNTO 0);"),CONCATENATE(A16," : IN std_logic_vector (15 DOWNTO 0);")) -> Timestamp1 : BUFFER std_logic_vector (15 DOWNTO 0); | AC16: =CONCATENATE("pl1553BaseAddress[c_w",A16, "] = 0x",F16,";") -> pl1553BaseAddress[c_wTimestamp1] = 0x0000;
A17: Timestamp0_LSB | B17: =B16+1 -> 15 | C17: =CONCATENATE("0x",DEC2HEX(B17,4)) -> 0x000F | D17: =CONCATENATE(A17," (",C17,")") -> Timestamp0_LSB (0x000F) | E17: Read/Write | F17: 0000 | G17: =CONCATENATE("0x",F17) -> 0x0000 | X17: =CONCATENATE("const static uint16_t c_w",A17, " = ",C17,";") -> const static uint16_t c_wTimestamp0_LSB = 0x000F; | Y17: =IF(E17<>"READ",CONCATENATE(A17," <= X""",F17,""";"),"") -> Timestamp0_LSB <= X"0000"; | Z17: =IF(E17<>"WRITE",CONCATENATE(" when X""",C17,""" => DataOut <= ",A17,";"),"") -> when X"0x000F" => DataOut <= Timestamp0_LSB; | AA17: =IF(E17<>"READ",CONCATENATE(" when X""",C17,""" => ",A17," <= DataIn;"),"") -> when X"0x000F" => Timestamp0_LSB <= DataIn; | AB17: =IF(E17<>"READ",CONCATENATE(A17," : BUFFER std_logic_vector (15 DOWNTO 0);"),CONCATENATE(A17," : IN std_logic_vector (15 DOWNTO 0);")) -> Timestamp0_LSB : BUFFER std_logic_vector (15 DOWNTO 0); | AC17: =CONCATENATE("pl1553BaseAddress[c_w",A17, "] = 0x",F17,";") -> pl1553BaseAddress[c_wTimestamp0_LSB] = 0x0000;
G19: uint16_t wDefaultValues[16] = { | H19: , | I19: };
A20: Discrete outputs | B20: 15 | G20: 0x0000 | H20: 0x0000 | I20: 0x0000 | J20: 0xBEEF | K20: 0x0100 | L20: 0x0000 | M20: 0x0000 | N20: 0x0000 | O20: 0x0000 | P20: 0x0000 | Q20: 0x0000 | R20: 0x0000 | S20: 0x0000 | T20: 0x0000 | U20: 0x0000 | V20: 0x0000 | W20: 0x0000
B21: =B20-1 -> 14 | G21: 0x0000 | H21: =CONCATENATE(G19,H20,H19,I20,H19,J20,H19,K20,H19,L20,H19,M20,H19,N20,H19,O20,H19,P20,H19,Q20,H19,R20,H19,S20,H19,T20,H19,U20,H19,V20,H19,W20,I19) -> uint16_t wDefaultValues[16] = {0x0000, 0x0000, 0xBEEF, 0x0100, 0x0000, 0x0000, 0x0000, 0x0000, 0x0000, 0x0000, 0x0000, 0x0000, 0x0000, 0x0000, 0x0000, 0x0000};
B22: =B21-1 -> 13 | G22: 0xBEEF
B23: =B22-1 -> 12 | G23: 0x0100
B24: =B23-1 -> 11 | G24: 0x0000
B25: =B24-1 -> 10 | G25: 0x0000
B26: =B25-1 -> 9 | G26: 0x0000
B27: =B26-1 -> 8 | G27: 0x0000
B28: =B27-1 -> 7 | G28: 0x0000
B29: =B28-1 -> 6 | G29: 0x0000
B30: =B29-1 -> 5 | G30: 0x0000
B31: =B30-1 -> 4 | G31: 0x0000
B32: =B31-1 -> 3 | G32: 0x0000
B33: =B32-1 -> 2 | G33: 0x0000
B34: =B33-1 -> 1 | D34: LED1 (when FLASHLEDS in reg_control=1) | G34: 0x0000
B35: =B34-1 -> 0 | D35: LED0 (when FLASHLEDS in reg_control=1) | G35: 0x0000
G36: QString qsNames[16] = {" | H36: ", " | I36: "};
D37: 1st | E37: 2nd | F37: total | G37: reg_status | H37: reg_status | I37: reg_intr_mask | J37: reg_gID | K37: reg_fw_version | L37: reg_mode_addr_wr | M37: reg_mode_addr_rd | N37: reg_control | O37: reg_sw_verison | P37: reg_8 | Q37: reg_9 | R37: reg_10 | S37: reg_11 | T37: Timestamp3_MSB | U37: Timestamp2 | V37: Timestamp1 | W37: Timestamp0_LSB
A38: Sync Data | B38: 150 | C38: 150 | D38: 157 | E38: 143 | F38: =E38+D38 -> 300 | G38: reg_intr_mask | H38: =CONCATENATE(G36,H37,H36,I37,H36,J37,H36,K37,H36,L37,H36,M37,H36,N37,H36,O37,H36,P37,H36,Q37,H36,R37,H36,S37,H36,T37,H36,U37,H36,V37,H36,W37,I36) -> QString qsNames[16] = {"reg_status", "reg_intr_mask", "reg_gID", "reg_fw_version", "reg_mode_addr_wr", "reg_mode_addr_rd", "reg_control", "reg_sw_verison", "reg_8", "reg_9", "reg_10", "reg_11", "Timestamp3_MSB", "Timestamp2", "Timestamp1", "Timestamp0_LSB"};
A39: Sync Cmd | B39: 150 | C39: 150 | D39: 221 | E39: 208 | F39: =E39+D39 -> 429 | G39: reg_gID
A40: One | B40: 50 | C40: 50 | D40: 43 | E40: 57 | F40: =E40+D40 -> 100 | G40: reg_fw_version
A41: Zero | B41: 50 | C41: 50 | F41: =E41+D41 -> 0 | G41: reg_mode_addr_wr
...

Sheet SerialProtocol
G1: 1 | H1: =G1+1 -> 2 | I1: =H1+1 -> 3 | J1: =I1+8 -> 11 | K1: =J1+2 -> 13 | L1: =K1+2 -> 15 | M1: =L1+1 -> 16 | N1: =DEC2HEX(N2,2) -> 15 | O1: =DEC2HEX(O2,2) -> 17 | P1: =DEC2HEX(P2,2) -> 19 | Q1: =DEC2HEX(Q2,2) -> 1B | R1: =DEC2HEX(R2,2) -> 1D | S1: =DEC2HEX(S2,2) -> 1F | T1: =DEC2HEX(T2,2) -> 21 | U1: =DEC2HEX(U2,2) -> 23 | ... AT1: =DEC2HEX(AT2,2) -> 54
D2: 0 | E2: =D2+1 -> 1 | F2: =E2+1 -> 2 | G2: =F2+1 -> 3 | H2: =G2+1 -> 4 | I2: =H2+1 -> 5 | J2: =I2+8 -> 13 | K2: =J2+2 -> 15 | L2: =K2+2 -> 17 | M2: =L2+2 -> 19 | N2: =M2+2 -> 21 | O2: =N2+2 -> 23 | P2: =O2+2 -> 25 | Q2: =P2+2 -> 27 | R2: =Q2+2 -> 29 | ... AS2: =AR2+2 -> 83 | AT2: =AS2+1 -> 84
A3: Msg ID | D3: SOM | E3: MSGID | F3: LEN | G3: SEQ | H3: BUS | I3: TIMESTAMP | J3: REG ADDR | K3: REG VALUE | L3: CMD | M3: DAT0 | N3: DAT1 | O3: DAT2 | P3: DAT3 | Q3: DAT4 | R3: DAT5 | S3: DAT6 | T3: DAT7 | U3: DAT8 | V3: DAT9 | W3: DAT10 | X3: DAT11 | Y3: DAT12 | Z3: DAT13 | AA3: DAT14 | AB3: DAT15 | AC3: DAT16 | AD3: DAT17 | AE3: DAT18 | AF3: DAT19 | AG3: DAT20 | AH3: DAT21 | AI3: DAT22 | AJ3: DAT23 | AK3: DAT24 | AL3: DAT25 | AM3: DAT26 | AN3: DAT27 | AO3: DAT28 | AP3: DAT29 | AQ3: DAT30 | AR3: DAT31 | AS3: CHK | AT3: EOM
A4: 0x01 | B4: HOST2MIL1553 | C4: Read a Register | D4: 0x7E | E4: =A4 -> 0x01 | F4: 14 | G4: 0-255 | H4: 0/1/2/3 | I4: 64bit time | J4: Addr to Read | K4: CHK | L4: EOM
A5: 0x11 | B5: MIL15532HOST | C5: Reply to Read register | D5: 0x7E | E5: =A5 -> 0x11 | F5: 16 | G5: 0-255 | H5: 0/1/2/3 | I5: 64bit time | J5: Addr Read | K5: Data Read | L5: CHK | M5: EOM
A6: 0x02 | B6: HOST2MIL1553 | C6: Write a Register | D6: 0x7E | E6: =A6 -> 0x02 | F6: 16 | G6: 0-255 | H6: 0/1/2/3 | I6: 64bit time | J6: Addr to Write | K6: Data 2 Write | L6: CHK | M6: EOM
A7: 0x12 | B7: MIL15532HOST | C7: Reply to Write register | D7: 0x7E | E7: =A7 -> 0x12 | F7: 16 | G7: 0-255 | H7: 0/1/2/3 | I7: 64bit time | J7: Written Addr | K7: Data Written | L7: CHK | M7: EOM
A8: 0x03 | B8: HOST2MIL1553 | C8: Read Receive Buffer | D8: 0x7E | E8: =A8 -> 0x03 | F8: 16 | G8: 0-255 | H8: 1/2 | I8: 64bit time | J8: Buff Addr to Read | K8: Rd Num Words | L8: CHK | M8: EOM
A9: 0x13 | B9: MIL15532HOST | C9: Reply to Read Receive Buffer | D9: 0x7E | E9: =A9 -> 0x13 | F9: 18 >> | G9: 0-255 | H9: 1/2 | I9: 64bit time | J9: Buf Addr Read | K9: Rd Num Words | L9: CMD/STAT | M9: Dat 0 | N9: Dat 1 | O9: Dat 2 | P9: Dat 3 | Q9: Dat 4 | R9: Dat 5 | S9: Dat 6 | T9: Dat 7 | U9: Dat 8 | V9: Dat 9 | W9: Dat 10 | X9: Dat 11 | Y9: Dat 12 | Z9: Dat 13 | AA9: Dat 14 | AB9: Dat 15 | AC9: Dat 16 | AD9: Dat 17 | AE9: Dat 18 | AF9: Dat 19 | AG9: Dat 20 | AH9: Dat 21 | AI9: Dat 22 | AJ9: Dat 23 | AK9: Dat 24 | AL9: Dat 25 | AM9: Dat 26 | AN9: Dat 27 | AO9: Dat 28 | AP9: Dat 29 | AQ9: Dat 30 | AR9: Dat 31 | AS9: CHK | AT9: EOM
A10: 0x04 | B10: HOST2MIL1553 | C10: Write to Transmit Buffer | D10: 0x7E | E10: =A10 -> 0x04 | F10: 18>> | G10: 0-255 | H10: 1/2 | I10: 64bit time | J10: Buf Addr to Write | K10: Wr Num Words | L10: CMD/STAT | M10: Dat 0 | N10: Dat 1 | O10: Dat 2 | P10: Dat 3 | Q10: Dat 4 | R10: Dat 5 | S10: Dat 6 | T10: Dat 7 | U10: Dat 8 | V10: Dat 9 | W10: Dat 10 | X10: Dat 11 | Y10: Dat 12 | Z10: Dat 13 | AA10: Dat 14 | AB10: Dat 15 | AC10: Dat 16 | AD10: Dat 17 | AE10: Dat 18 | AF10: Dat 19 | AG10: Dat 20 | AH10: Dat 21 | AI10: Dat 22 | AJ10: Dat 23 | AK10: Dat 24 | AL10: Dat 25 | AM10: Dat 26 | AN10: Dat 27 | AO10: Dat 28 | AP10: Dat 29 | AQ10: Dat 30 | AR10: Dat 31 | AS10: CHK | AT10: EOM
A11: 0x14 | B11: MIL15532HOST | C11: Reply to Write Transmit Buffer | D11: 0x7E | E11: =A11 -> 0x14 | F11: 18>> | G11: 0-255 | H11: 1/2 | I11: 64bit time | J11: Buf Addr Written | K11: Wr Num Words | L11: CMD/STAT | M11: Dat 0 | N11: Dat 1 | O11: Dat 2 | P11: Dat 3 | Q11: Dat 4 | R11: Dat 5 | S11: Dat 6 | T11: Dat 7 | U11: Dat 8 | V11: Dat 9 | W11: Dat 10 | X11: Dat 11 | Y11: Dat 12 | Z11: Dat 13 | AA11: Dat 14 | AB11: Dat 15 | AC11: Dat 16 | AD11: Dat 17 | AE11: Dat 18 | AF11: Dat 19 | AG11: Dat 20 | AH11: Dat 21 | AI11: Dat 22 | AJ11: Dat 23 | AK11: Dat 24 | AL11: Dat 25 | AM11: Dat 26 | AN11: Dat 27 | AO11: Dat 28 | AP11: Dat 29 | AQ11: Dat 30 | AR11: Dat 31 | AS11: CHK | AT11: EOM
A12: 0x05 | B12: HOST2MIL1553 | C12: Write a MIL1553 Register | D12: 0x7E | E12: =A12 -> 0x05 | F12: 16 | G12: 0-255 | H12: 1/2 | I12: 64bit time | J12: Addr to Write | K12: Data 2 Write | L12: CHK | M12: EOM
A13: 0x15 | B13: MIL15532HOST | C13: Reply to Write MIL1553 register | D13: 0x7E | E13: =A13 -> 0x15 | F13: 16 | G13: 0-255 | H13: 1/2 | I13: 64bit time | J13: Written Addr | K13: Data Written | L13: CHK | M13: EOM
L14: Len for numb Data words | N14: Words:
B15: SOM | C15: Always written as 0x7E | K15: Total | L15: LEN | M15: WORD | O15: END
B16: MSGID | C16: Message ID, MSB Nibble indicates direction 0 is to Converter, 1 is from converter | K16: =L16+3 -> 23 | L16: =16+N16+O16 -> 20 | M16: 1 | N16: =M16*2 -> 2 | O16: 2
B17: LEN | C17: Length of bytes, from SEQ to CHK excluding EOM
B18: SEQ | C18: Sequnece number running rom 0 to 255 and wrapping. Separate seqeunce numbers for transmit and receive
B19: BUS | C19: 0 = core general, 1 = core bus 1, 2 = core bus 2, 3 = converter registers
B20: TIMESTAMP | C20: Computer unix time when sending message, Converter does not use it. Converter timestamp on return message
B21: REG ADDR | C21: Register address when writing to a registers
B22: REG VALUE | C22: Register value when writing to a register
B23: CHK | C23: XOR Checksum of all bytes from MSGID to last data byte. Reset to 0x00 at start of message.
B24: EOM | C24: Always written as 0xE7
B25: CMD/STAT
B26: NUMWORDS | C26: Number of data words to follow. When register write this is set to 0
B27: Addr to Read | C27: Addres of register to read. When bus is 0, the default register address can be used, when 1 or 2, the LSB byte of register can be used to read the register for the relevant bus. Range is from 0x00 to 0x3F. Please note that there are reserved registers in this range.
B28: Addr Read | C28: Return the Addr that was read from.
B29: Addr to Write | C29: Addres of register to write. When bus is 0, the default register address can be used, when 1 or 2, the LSB byte of register can be used to read the register for the relevant bus. Range is from 0x00 to 0x3F. Please note that there are reserved registers in this range.
B30: Written Addr | C30: Return the addr of the register written
B31: Buff Addr to Read | C31: Address of buffer to read. Refer to MemMap sheet.
B32: Buf Addr Read | C32: Returns the buffer address read
B33: Buf Addr to Write | C33: Address of buffer to write. Refer to MemMap sheet.
B34: Buf Addr Written | C34: Returns the buffer address written
B35: Mode/Addr | C35: Sets the mode of the converter, the address lines and the enables for unsolicted message for certain events
B36: Stat/Mode/Addr | C36: Returns status and the mode of the converter, the address lines and the enables for unsolicted message for certain events
D38: Bit15 | E38: Bit14 | F38: Bit13 | J38: Bit11 | K38: Bit9 | M38: Bit7 | N38: Bit6 | O38: Bit5 | P38: Bit4 | Q38: Bit3 | R38: Bit2 | S38: Bit1 | T38: Bit0
C39: MODE/ADDR | D39: MON | E39: RT | F39: BC | J39: TX EMPTY | K39: 28V1 | M39: INT | N39: REL | O39: PAR | P39: ADR4 | Q39: ADR3 | R39: ADR2 | S39: ADR1 | T39: ADR0
C40: STATUS

Sheet Mode Commands
A1: TxnRx | B1: ModeMSB | C1: Mode | D1: Mode | F1: Addressed RT Response | G1: Broadcast response
A2: 0 | B2: 0 | C2: 0 | D2: 0 | E2: =DEC2HEX(C2,1) -> 0 | F2: NRP | G2: NRP
A3: 0 | B3: 0 | C3: =C2+1 -> 1 | D3: 0 | E3: =DEC2HEX(C3,1) -> 1 | F3: NRP | G3: NRP
A4: 0 | B4: 0 | C4: =C3+1 -> 2 | D4: 0 | E4: =DEC2HEX(C4,1) -> 2 | F4: NRP | G4: NRP
A5: 0 | B5: 0 | C5: =C4+1 -> 3 | D5: 0 | E5: =DEC2HEX(C5,1) -> 3 | F5: NRP | G5: NRP
A6: 0 | B6: 0 | C6: =C5+1 -> 4 | D6: 0 | E6: =DEC2HEX(C6,1) -> 4 | F6: NRP | G6: NRP
A7: 0 | B7: 0 | C7: =C6+1 -> 5 | D7: 0 | E7: =DEC2HEX(C7,1) -> 5 | F7: NRP | G7: NRP
A8: 0 | B8: 0 | C8: =C7+1 -> 6 | D8: 0 | E8: =DEC2HEX(C8,1) -> 6 | F8: NRP | G8: NRP
A9: 0 | B9: 0 | C9: =C8+1 -> 7 | D9: 0 | E9: =DEC2HEX(C9,1) -> 7 | F9: NRP | G9: NRP
A10: 0 | B10: 0 | C10: =C9+1 -> 8 | D10: 0 | E10: =DEC2HEX(C10,1) -> 8 | F10: NRP | G10: NRP
A11: 0 | B11: 0 | C11: =C10+1 -> 9 | D11: 0 | E11: =DEC2HEX(C11,1) -> 9 | F11: NRP | G11: NRP
A12: 0 | B12: 0 | C12: =C11+1 -> 10 | D12: 0 | E12: =DEC2HEX(C12,1) -> A | F12: NRP | G12: NRP
A13: 0 | B13: 0 | C13: =C12+1 -> 11 | D13: 0 | E13: =DEC2HEX(C13,1) -> B | F13: NRP | G13: NRP
A14: 0 | B14: 0 | C14: =C13+1 -> 12 | D14: 0 | E14: =DEC2HEX(C14,1) -> C | F14: NRP | G14: NRP
... A17: 0 | B17: 0 | C17: =C16+1 -> 15 | D17: 0 | E17: =DEC2HEX(C17,1) -> F | F17: NRP | G17: NRP
A18: 0 | B18: 1 | C18: 0 | D18: 1 | E18: =DEC2HEX(C18,1) -> 0 | F18: NRP | G18: NRP
A19: 0 | B19: 1 | C19: =C18+1 -> 1 | D19: 1 | E19: =DEC2HEX(C19,1) -> 1 | F19: Synchronize | G19: Synchronize
A20: 0 | B20: 1 | C20: =C19+1 -> 2 | D20: 1 | E20: =DEC2HEX(C20,1) -> 2 | F20: NRP | G20: NRP
A21: 0 | B21: 1 | C21: =C20+1 -> 3 | D21: 1 | E21: =DEC2HEX(C21,1) -> 3 | F21: NRP | G21: NRP
A22: 0 | B22: 1 | C22: =C21+1 -> 4 | D22: 1 | E22: =DEC2HEX(C22,1) -> 4 | F22: Selected transmitter shutdown | G22: Selected transmitter shutdown
A23: 0 | B23: 1 | C23: =C22+1 -> 5 | D23: 1 | E23: =DEC2HEX(C23,1) -> 5 | F23: Override selected transmitter shutdown | G23: Override selected transmitter shutdown
A24: 0 | B24: 1 | C24: =C23+1 -> 6 | D24: 1 | E24: =DEC2HEX(C24,1) -> 6 | F24: NRP | G24: NRP
A25: 0 | B25: 1 | C25: =C24+1 -> 7 | D25: 1 | E25: =DEC2HEX(C25,1) -> 7 | F25: NRP | G25: NRP
A26: 0 | B26: 1 | C26: =C25+1 -> 8 | D26: 1 | E26: =DEC2HEX(C26,1) -> 8 | F26: NRP | G26: NRP
A27: 0 | B27: 1 | C27: =C26+1 -> 9 | D27: 1 | E27: =DEC2HEX(C27,1) -> 9 | F27: NRP | G27: NRP
A28: 0 | B28: 1 | C28: =C27+1 -> 10 | D28: 1 | E28: =DEC2HEX(C28,1) -> A | F28: NRP | G28: NRP
A29: 0 | B29: 1 | C29: =C28+1 -> 11 | D29: 1 | E29: =DEC2HEX(C29,1) -> B | F29: NRP | G29: NRP
A30: 0 | B30: 1 | C30: =C29+1 -> 12 | D30: 1 | E30: =DEC2HEX(C30,1) -> C | F30: NRP | G30: NRP
... A33: 0 | B33: 1 | C33: =C32+1 -> 15 | D33: 1 | E33: =DEC2HEX(C33,1) -> F | F33: NRP | G33: NRP
A34: 1 | B34: 0 | C34: 0 | D34: 0 | E34: =DEC2HEX(C34,1) -> 0 | F34: Dynamic Bus Control | G34: NRP
A35: 1 | B35: 0 | C35: =C34+1 -> 1 | D35: 0 | E35: =DEC2HEX(C35,1) -> 1 | F35: Synchronize | G35: Synchronize
A36: 1 | B36: 0 | C36: =C35+1 -> 2 | D36: 0 | E36: =DEC2HEX(C36,1) -> 2 | F36: Transmit status word | G36: NRP
A37: 1 | B37: 0 | C37: =C36+1 -> 3 | D37: 0 | E37: =DEC2HEX(C37,1) -> 3 | F37: Initiate Self test | G37: Initiate Self test
A38: 1 | B38: 0 | C38: =C37+1 -> 4 | D38: 0 | E38: =DEC2HEX(C38,1) -> 4 | F38: Transmitter shutdown | G38: Transmitter shutdown
A39: 1 | B39: 0 | C39: =C38+1 -> 5 | D39: 0 | E39: =DEC2HEX(C39,1) -> 5 | F39: Override transmitter shutdown | G39: Override transmitter shutdown
A40: 1 | B40: 0 | C40: =C39+1 -> 6 | D40: 0 | E40: =DEC2HEX(C40,1) -> 6 | F40: Inhibit Terminal flag | G40: Inhibit Terminal flag
A41: 1 | B41: 0 | C41: =C40+1 -> 7 | D41: 0 | E41: =DEC2HEX(C41,1) -> 7 | F41: Override inhibit terminal flag | G41: Override inhibit terminal flag
A42: 1 | B42: 0 | C42: =C41+1 -> 8 | D42: 0 | E42: =DEC2HEX(C42,1) -> 8 | F42: Reset Remote Terminal | G42: Reset Remote Terminal
A43: 1 | B43: 0 | C43: =C42+1 -> 9 | D43: 0 | E43: =DEC2HEX(C43,1) -> 9 | F43: NRP | G43: NRP
A44: 1 | B44: 0 | C44: =C43+1 -> 10 | D44: 0 | E44: =DEC2HEX(C44,1) -> A | F44: NRP | G44: NRP
...

Sheet MemoryMap
A2: 0 | B2: =CONCATENATE("0x",DEC2HEX(A2,4)) -> 0x0000 | C2: Start | D2: Registers | E2: Common registers | O2: =C2 -> Start | P2: =C3 -> End | Q2: Size | R2: Function
